[2024-07-19T18:07:12.190+0000] {local_task_job_runner.py:120} INFO - ::group::Pre task execution logs
[2024-07-19T18:07:12.272+0000] {taskinstance.py:2076} INFO - Dependencies all met for dep_context=non-requeueable deps ti=<TaskInstance: insert_data.md_exchange_rate_d manual__2024-07-19T18:06:55.309501+00:00 [queued]>
[2024-07-19T18:07:12.290+0000] {taskinstance.py:2076} INFO - Dependencies all met for dep_context=requeueable deps ti=<TaskInstance: insert_data.md_exchange_rate_d manual__2024-07-19T18:06:55.309501+00:00 [queued]>
[2024-07-19T18:07:12.299+0000] {taskinstance.py:2306} INFO - Starting attempt 1 of 3
[2024-07-19T18:07:12.377+0000] {taskinstance.py:2330} INFO - Executing <Task(PythonOperator): md_exchange_rate_d> on 2024-07-19 18:06:55.309501+00:00
[2024-07-19T18:07:12.411+0000] {warnings.py:112} WARNING - /home/***/.local/lib/python3.12/site-packages/***/task/task_runner/standard_task_runner.py:62: DeprecationWarning: This process (pid=3727) is multi-threaded, use of fork() may lead to deadlocks in the child.
  pid = os.fork()

[2024-07-19T18:07:12.421+0000] {standard_task_runner.py:64} INFO - Started process 3738 to run task
[2024-07-19T18:07:12.437+0000] {standard_task_runner.py:90} INFO - Running: ['***', 'tasks', 'run', 'insert_data', 'md_exchange_rate_d', 'manual__2024-07-19T18:06:55.309501+00:00', '--job-id', '359', '--raw', '--subdir', 'DAGS_FOLDER/insert_data.py', '--cfg-path', '/tmp/tmp_gqsh0ui']
[2024-07-19T18:07:12.439+0000] {standard_task_runner.py:91} INFO - Job 359: Subtask md_exchange_rate_d
[2024-07-19T18:07:12.652+0000] {task_command.py:426} INFO - Running <TaskInstance: insert_data.md_exchange_rate_d manual__2024-07-19T18:06:55.309501+00:00 [running]> on host 04b0ec8dd5cd
[2024-07-19T18:07:13.062+0000] {taskinstance.py:2648} INFO - Exporting env vars: AIRFLOW_CTX_DAG_OWNER='sfakhrutdinov' AIRFLOW_CTX_DAG_ID='insert_data' AIRFLOW_CTX_TASK_ID='md_exchange_rate_d' AIRFLOW_CTX_EXECUTION_DATE='2024-07-19T18:06:55.309501+00:00' AIRFLOW_CTX_TRY_NUMBER='1' AIRFLOW_CTX_DAG_RUN_ID='manual__2024-07-19T18:06:55.309501+00:00'
[2024-07-19T18:07:13.074+0000] {taskinstance.py:430} INFO - ::endgroup::
[2024-07-19T18:07:13.292+0000] {base.py:84} INFO - Using connection ID 'postgres-db' for task execution.
[2024-07-19T18:07:14.051+0000] {taskinstance.py:441} INFO - ::group::Post task execution logs
[2024-07-19T18:07:14.078+0000] {taskinstance.py:2905} ERROR - Task failed with exception
Traceback (most recent call last):
  File "/home/airflow/.local/lib/python3.12/site-packages/sqlalchemy/engine/base.py", line 1890, in _execute_context
    self.dialect.do_executemany(
  File "/home/airflow/.local/lib/python3.12/site-packages/sqlalchemy/dialects/postgresql/psycopg2.py", line 982, in do_executemany
    context._psycopg2_fetched_rows = xtras.execute_values(
                                     ^^^^^^^^^^^^^^^^^^^^^
  File "/home/airflow/.local/lib/python3.12/site-packages/psycopg2/extras.py", line 1299, in execute_values
    cur.execute(b''.join(parts))
psycopg2.errors.UndefinedColumn: column "DATA_ACTUAL_DATE" of relation "md_exchange_rate_d" does not exist
LINE 1: INSERT INTO ds.md_exchange_rate_d ("DATA_ACTUAL_DATE", "DATA...
                                           ^


The above exception was the direct cause of the following exception:

Traceback (most recent call last):
  File "/home/airflow/.local/lib/python3.12/site-packages/airflow/models/taskinstance.py", line 465, in _execute_task
    result = _execute_callable(context=context, **execute_callable_kwargs)
             ^^^^^^^^^^^^^^^^^^^^^^^^^^^^^^^^^^^^^^^^^^^^^^^^^^^^^^^^^^^^^
  File "/home/airflow/.local/lib/python3.12/site-packages/airflow/models/taskinstance.py", line 432, in _execute_callable
    return execute_callable(context=context, **execute_callable_kwargs)
           ^^^^^^^^^^^^^^^^^^^^^^^^^^^^^^^^^^^^^^^^^^^^^^^^^^^^^^^^^^^^
  File "/home/airflow/.local/lib/python3.12/site-packages/airflow/models/baseoperator.py", line 401, in wrapper
    return func(self, *args, **kwargs)
           ^^^^^^^^^^^^^^^^^^^^^^^^^^^
  File "/home/airflow/.local/lib/python3.12/site-packages/airflow/operators/python.py", line 235, in execute
    return_value = self.execute_callable()
                   ^^^^^^^^^^^^^^^^^^^^^^^
  File "/home/airflow/.local/lib/python3.12/site-packages/airflow/operators/python.py", line 252, in execute_callable
    return self.python_callable(*self.op_args, **self.op_kwargs)
           ^^^^^^^^^^^^^^^^^^^^^^^^^^^^^^^^^^^^^^^^^^^^^^^^^^^^^
  File "/opt/airflow/dags/insert_data.py", line 13, in insert_data
    df.to_sql(table_name, engine, schema="ds", if_exists="append", index=False)
  File "/home/airflow/.local/lib/python3.12/site-packages/pandas/util/_decorators.py", line 333, in wrapper
    return func(*args, **kwargs)
           ^^^^^^^^^^^^^^^^^^^^^
  File "/home/airflow/.local/lib/python3.12/site-packages/pandas/core/generic.py", line 3008, in to_sql
    return sql.to_sql(
           ^^^^^^^^^^^
  File "/home/airflow/.local/lib/python3.12/site-packages/pandas/io/sql.py", line 788, in to_sql
    return pandas_sql.to_sql(
           ^^^^^^^^^^^^^^^^^^
  File "/home/airflow/.local/lib/python3.12/site-packages/pandas/io/sql.py", line 1958, in to_sql
    total_inserted = sql_engine.insert_records(
                     ^^^^^^^^^^^^^^^^^^^^^^^^^^
  File "/home/airflow/.local/lib/python3.12/site-packages/pandas/io/sql.py", line 1507, in insert_records
    raise err
  File "/home/airflow/.local/lib/python3.12/site-packages/pandas/io/sql.py", line 1498, in insert_records
    return table.insert(chunksize=chunksize, method=method)
           ^^^^^^^^^^^^^^^^^^^^^^^^^^^^^^^^^^^^^^^^^^^^^^^^
  File "/home/airflow/.local/lib/python3.12/site-packages/pandas/io/sql.py", line 1059, in insert
    num_inserted = exec_insert(conn, keys, chunk_iter)
                   ^^^^^^^^^^^^^^^^^^^^^^^^^^^^^^^^^^^
  File "/home/airflow/.local/lib/python3.12/site-packages/pandas/io/sql.py", line 951, in _execute_insert
    result = conn.execute(self.table.insert(), data)
             ^^^^^^^^^^^^^^^^^^^^^^^^^^^^^^^^^^^^^^^
  File "/home/airflow/.local/lib/python3.12/site-packages/sqlalchemy/engine/base.py", line 1385, in execute
    return meth(self, multiparams, params, _EMPTY_EXECUTION_OPTS)
           ^^^^^^^^^^^^^^^^^^^^^^^^^^^^^^^^^^^^^^^^^^^^^^^^^^^^^^
  File "/home/airflow/.local/lib/python3.12/site-packages/sqlalchemy/sql/elements.py", line 334, in _execute_on_connection
    return connection._execute_clauseelement(
           ^^^^^^^^^^^^^^^^^^^^^^^^^^^^^^^^^^
  File "/home/airflow/.local/lib/python3.12/site-packages/sqlalchemy/engine/base.py", line 1577, in _execute_clauseelement
    ret = self._execute_context(
          ^^^^^^^^^^^^^^^^^^^^^^
  File "/home/airflow/.local/lib/python3.12/site-packages/sqlalchemy/engine/base.py", line 1953, in _execute_context
    self._handle_dbapi_exception(
  File "/home/airflow/.local/lib/python3.12/site-packages/sqlalchemy/engine/base.py", line 2134, in _handle_dbapi_exception
    util.raise_(
  File "/home/airflow/.local/lib/python3.12/site-packages/sqlalchemy/util/compat.py", line 211, in raise_
    raise exception
  File "/home/airflow/.local/lib/python3.12/site-packages/sqlalchemy/engine/base.py", line 1890, in _execute_context
    self.dialect.do_executemany(
  File "/home/airflow/.local/lib/python3.12/site-packages/sqlalchemy/dialects/postgresql/psycopg2.py", line 982, in do_executemany
    context._psycopg2_fetched_rows = xtras.execute_values(
                                     ^^^^^^^^^^^^^^^^^^^^^
  File "/home/airflow/.local/lib/python3.12/site-packages/psycopg2/extras.py", line 1299, in execute_values
    cur.execute(b''.join(parts))
sqlalchemy.exc.ProgrammingError: (psycopg2.errors.UndefinedColumn) column "DATA_ACTUAL_DATE" of relation "md_exchange_rate_d" does not exist
LINE 1: INSERT INTO ds.md_exchange_rate_d ("DATA_ACTUAL_DATE", "DATA...
                                           ^

[SQL: INSERT INTO ds.md_exchange_rate_d ("DATA_ACTUAL_DATE", "DATA_ACTUAL_END_DATE", "CURRENCY_RK", "REDUCED_COURCE", "CODE_ISO_NUM") VALUES (%(DATA_ACTUAL_DATE)s, %(DATA_ACTUAL_END_DATE)s, %(CURRENCY_RK)s, %(REDUCED_COURCE)s, %(CODE_ISO_NUM)s)]
[parameters: ({'DATA_ACTUAL_DATE': '2016-07-01', 'DATA_ACTUAL_END_DATE': '2050-12-31', 'CURRENCY_RK': 38, 'REDUCED_COURCE': 31.8884, 'CODE_ISO_NUM': 974}, {'DATA_ACTUAL_DATE': '2018-01-31', 'DATA_ACTUAL_END_DATE': '2018-01-31', 'CURRENCY_RK': 427870281, 'REDUCED_COURCE': 28.3798, 'CODE_ISO_NUM': 933}, {'DATA_ACTUAL_DATE': '2018-01-31', 'DATA_ACTUAL_END_DATE': '2018-01-31', 'CURRENCY_RK': 29, 'REDUCED_COURCE': 7.11613, 'CODE_ISO_NUM': 752}, {'DATA_ACTUAL_DATE': '2018-01-31', 'DATA_ACTUAL_END_DATE': '2018-01-31', 'CURRENCY_RK': 529511970, 'REDUCED_COURCE': 33.0543, 'CODE_ISO_NUM': 944}, {'DATA_ACTUAL_DATE': '2018-01-31', 'DATA_ACTUAL_END_DATE': '2018-01-31', 'CURRENCY_RK': 62, 'REDUCED_COURCE': 8.87555, 'CODE_ISO_NUM': 156}, {'DATA_ACTUAL_DATE': '2018-01-31', 'DATA_ACTUAL_END_DATE': '2018-01-31', 'CURRENCY_RK': 205699733, 'REDUCED_COURCE': 2.74512, 'CODE_ISO_NUM': 203}, {'DATA_ACTUAL_DATE': '2018-01-31', 'DATA_ACTUAL_END_DATE': '2018-01-31', 'CURRENCY_RK': 205699734, 'REDUCED_COURCE': 0.224063, 'CODE_ISO_NUM': 348}, {'DATA_ACTUAL_DATE': '2018-01-31', 'DATA_ACTUAL_END_DATE': '2018-01-31', 'CURRENCY_RK': 409611215, 'REDUCED_COURCE': 6.37718, 'CODE_ISO_NUM': 972}  ... displaying 10 of 892 total bound parameter sets ...  {'DATA_ACTUAL_DATE': '2017-12-30', 'DATA_ACTUAL_END_DATE': '2018-01-09', 'CURRENCY_RK': 529511970, 'REDUCED_COURCE': 33.8228, 'CODE_ISO_NUM': 944}, {'DATA_ACTUAL_DATE': '2017-12-30', 'DATA_ACTUAL_END_DATE': '2018-01-09', 'CURRENCY_RK': 25, 'REDUCED_COURCE': 17.3887, 'CODE_ISO_NUM': 986})]
(Background on this error at: https://sqlalche.me/e/14/f405)
[2024-07-19T18:07:14.469+0000] {taskinstance.py:1206} INFO - Marking task as UP_FOR_RETRY. dag_id=insert_data, task_id=md_exchange_rate_d, run_id=manual__2024-07-19T18:06:55.309501+00:00, execution_date=20240719T180655, start_date=20240719T180712, end_date=20240719T180714
[2024-07-19T18:07:14.603+0000] {standard_task_runner.py:110} ERROR - Failed to execute job 359 for task md_exchange_rate_d ((psycopg2.errors.UndefinedColumn) column "DATA_ACTUAL_DATE" of relation "md_exchange_rate_d" does not exist
LINE 1: INSERT INTO ds.md_exchange_rate_d ("DATA_ACTUAL_DATE", "DATA...
                                           ^

[SQL: INSERT INTO ds.md_exchange_rate_d ("DATA_ACTUAL_DATE", "DATA_ACTUAL_END_DATE", "CURRENCY_RK", "REDUCED_COURCE", "CODE_ISO_NUM") VALUES (%(DATA_ACTUAL_DATE)s, %(DATA_ACTUAL_END_DATE)s, %(CURRENCY_RK)s, %(REDUCED_COURCE)s, %(CODE_ISO_NUM)s)]
[parameters: ({'DATA_ACTUAL_DATE': '2016-07-01', 'DATA_ACTUAL_END_DATE': '2050-12-31', 'CURRENCY_RK': 38, 'REDUCED_COURCE': 31.8884, 'CODE_ISO_NUM': 974}, {'DATA_ACTUAL_DATE': '2018-01-31', 'DATA_ACTUAL_END_DATE': '2018-01-31', 'CURRENCY_RK': 427870281, 'REDUCED_COURCE': 28.3798, 'CODE_ISO_NUM': 933}, {'DATA_ACTUAL_DATE': '2018-01-31', 'DATA_ACTUAL_END_DATE': '2018-01-31', 'CURRENCY_RK': 29, 'REDUCED_COURCE': 7.11613, 'CODE_ISO_NUM': 752}, {'DATA_ACTUAL_DATE': '2018-01-31', 'DATA_ACTUAL_END_DATE': '2018-01-31', 'CURRENCY_RK': 529511970, 'REDUCED_COURCE': 33.0543, 'CODE_ISO_NUM': 944}, {'DATA_ACTUAL_DATE': '2018-01-31', 'DATA_ACTUAL_END_DATE': '2018-01-31', 'CURRENCY_RK': 62, 'REDUCED_COURCE': 8.87555, 'CODE_ISO_NUM': 156}, {'DATA_ACTUAL_DATE': '2018-01-31', 'DATA_ACTUAL_END_DATE': '2018-01-31', 'CURRENCY_RK': 205699733, 'REDUCED_COURCE': 2.74512, 'CODE_ISO_NUM': 203}, {'DATA_ACTUAL_DATE': '2018-01-31', 'DATA_ACTUAL_END_DATE': '2018-01-31', 'CURRENCY_RK': 205699734, 'REDUCED_COURCE': 0.224063, 'CODE_ISO_NUM': 348}, {'DATA_ACTUAL_DATE': '2018-01-31', 'DATA_ACTUAL_END_DATE': '2018-01-31', 'CURRENCY_RK': 409611215, 'REDUCED_COURCE': 6.37718, 'CODE_ISO_NUM': 972}  ... displaying 10 of 892 total bound parameter sets ...  {'DATA_ACTUAL_DATE': '2017-12-30', 'DATA_ACTUAL_END_DATE': '2018-01-09', 'CURRENCY_RK': 529511970, 'REDUCED_COURCE': 33.8228, 'CODE_ISO_NUM': 944}, {'DATA_ACTUAL_DATE': '2017-12-30', 'DATA_ACTUAL_END_DATE': '2018-01-09', 'CURRENCY_RK': 25, 'REDUCED_COURCE': 17.3887, 'CODE_ISO_NUM': 986})]
(Background on this error at: https://sqlalche.me/e/14/f405); 3738)
[2024-07-19T18:07:14.751+0000] {local_task_job_runner.py:243} INFO - Task exited with return code 1
[2024-07-19T18:07:14.988+0000] {local_task_job_runner.py:222} INFO - ::endgroup::
